Workbook
Name New: #REF!
Name New: SupportData!$A$8:$E$32
Name ProductLines: #REF!
Name ProductLines: SupportData!$A$53:$E$65
Name qrySwatchLine6cCurrent: '3x5 Leather'!$A$15:$G$166
Name qrySwatchLine6cDrop: '3x5 Leather'!#REF!
Name qrySwatchLine6iCurrent: '6x6 Fabric'!$A$10:$G$443
Name qrySwatchLineClCurrent: 'Select Stationary Leather'!$A$14:$L$18
Name qrySwatchLineCsCurrent: 'Select Fabrics 12 x 12'!$A$25:$M$27
Name qrySwatchLineDcCurrent: 'Design Center'!$A$11:$P$542
Name qrySwatchLineDcDrop: 'Design Center'!#REF!
Name qrySwatchLineExCurrent: 'Custom Leather Plus'!$A$10:$L$17
Name qrySwatchLineExCurrent: 'Specialty Leather Handle'!#REF!
Name qrySwatchLineExCurrent: 'Specialty Leather Ring Page'!$A$10:$L$16
Name qrySwatchLineExDrop: 'Custom Leather'!#REF!
Name qrySwatchLineExDrop: 'Custom Leather Plus'!#REF!
Name qrySwatchLineExDrop: 'Specialty Leather Ring Page'!#REF!
Name qrySwatchLineFcCurrent: 'Fringe and Cord'!$A$11:$K$18
Name qrySwatchLineKwCurrent: 'Cut and Sewn Fabric Waterfalls'!$A$10:$V$75
Name qrySwatchLineKwDrop: 'Cut and Sewn Fabric Waterfalls'!#REF!
Name qrySwatchLineLrCurrent: '2x3 Leather'!$A$9:$G$88
Name qrySwatchLineLrDrop: '2x3 Leather'!#REF!
Name qrySwatchLineLwCurrent: 'Cut and Sewn Leather Waterfalls'!$A$10:$O$71
Name qrySwatchLineLwDrop: 'Cut and Sewn Leather Waterfalls'!#REF!
Name qrySwatchLineMuCurrent: 'Ring Pages - Complete Set'!$A$9:$L$268
Name qrySwatchLineMuCurrent_2: 'MASTER FABRICS'!$A$13:$P$199
Name qrySwatchLineSlCurrent: 'Select Reclining Leather'!$A$11:$H$91
Name qrySwatchLineSlDrop: 'Select Reclining Leather'!#REF!
Name SwatchCovers: #REF!
Name SwatchCovers: #REF!
Name SwatchLines: #REF!
Name SwatchLines: SupportData!$A$8:$E$32
Name SwatchProfiles: #REF!
Name SwatchProfiles: #REF!
Name SwatchTypes: #REF!
Name SwatchTypes: SupportData!$A$37:$D$48

Sheet MASTER FABRICS
A1: All Active Fabric SKU's as of April 2026 Market
A3: Fabric Wearability Descriptions | J3: Pillow Program | K3: Specialty Fabric Descriptions | L3: Key:
A4: Normal | B4: (Black Dot) This fabric is recommended for use on all La-Z-Boy upholstered furniture. | J4: Pillows are NOT available in LL, LS, LM, RL, BU or UE cap codes | K4: I = iClean | L4: Immediate Drop
A5: Medium | B5: (Green Dot) This fabric is recommended for use on sofas, sleep sofas, Duo, La-Z-Boy Classics, | K5: C = Conserve | L5: Phase Outs
B6: and Occasional chairs. It is not allowed for use on recliners, motion sofas or motion modulars. | K6: A = Antimicrobial | L6: New Phase Outs
A7: Performance | B7: (P Dot) This fabric is recommended for use on all La-Z-Boy upholstered furniture. While | K7: PF = Pet Friendly | L7: April 2026 Drops
B8: La-Z-Boy's fabrics are all tested to the highest industry standards, Performance Fabrics must receive | K8: N = Nanobionic
B9: excellent ratings for physical durability. Performance fabrics outperform other fabrics by receiving | K9: W*B = Bleach Cleanable
B10: outstanding results for pilling, abrasion and fraying.
A12: Series Number | B12: Pattern Name | C12: Colors | D12: # of SKU's | E12: Product Line | F12: Intro Date | G12: Horiz. Repeat | H12: Vertical Repeat | I12: CAP Code | J12: Face Contents | K12: Back Contents | L12: Wearability | M12: Specialty Fabric | N12: Welt Pattern | O12: Slip Cover Program | P12: Cleaning Code | Q12: Description(s)
A13: B1538 | B13: Seamount | C13: 76 = Cappuccino 74 = Sable 08 = Burgundy 53 = Silver 85 = Indigo | D13: 5 | E13: CH | F13: 43009 | G13: 0 | H13: 0 | I13: UR | J13: 100% Polyester | L13: N | P13: S | Q13: Seamount is a 100% polyester microfiber that has been processed with a woven backing for stability. Color is applied through a piece dye process to create depth. A subtle herringbone pattern makes this cover a trendy visual for any space.
A14: B1662 | B14: Rodigo | C14: 57 = Stone 78 = Walnut 86 = Navy 76 = Marsh | D14: 4 | E14: MU | F14: 43556 | G14: 0 | H14: 0 | I14: UR | J14: 100% Polyester | L14: P | P14: WS
A15: B1808 | B15: Social Club | C15: 52 = Stone 57 = Charcoal 68 = Pewter 72 = Chalk 76 = Cocoa | D15: 5 | E15: MU | F15: 44287 | G15: 0 | H15: 0 | I15: DR | J15: 100% Polyester | L15: P | P15: S | Q15: A super soft low pile pieced dyed chenille that has a subtle spaced dyed warp which gives a cross hatch like contrast with a speckled black dot design. The product is backed with a standard acrylic latex backing.
A16: B1827 | B16: Brink | C16: 25 = Lentil 86 = Slate | D16: 2 | E16: MU | F16: 44287 | G16: 0 | H16: 0 | I16: DR | J16: 100% Polyester | L16: N | P16: S | Q16: Brink is a multi-color plain with nubby space-dyed yarns, giving Brink both surface and visual texture. Each of the colorways offers enough shade variation to be used as blue, beige, gray, and green. Using 100% polyester yarns, Brink passes heavy duty wearability so it can be used as a new look textural motion cover, as well as a flat weave stationary fabric.
A17: C1371 | B17: Seasons | C17: 66 = Mocha 62 = Khaki 78 = Chocolate 28 = Loden 87 = Charcoal 08 = Redwood | D17: 6 | E17: MU | F17: 42278 | G17: 0 | H17: 0 | I17: DR | J17: 100% Polyester | L17: N | P17: S
A18: C1516 | B18: Merit | C18: 51 = Platinum 31 = Dove 57 = Charcoal | D18: 5 | E18: MU | F18: 42826 | G18: 0 | H18: 0 | I18: DR | J18: 100% Polyester | L18: N | P18: WS
A19: C1525 | B19: Roma | C19: 53 = Storm 78 = Espresso 74 = Mocha 86 = Navy 34 = Cream | D19: 5 | E19: CH | F19: 42826 | G19: 0 | H19: 0 | I19: DR | J19: 100% Polyester | L19: N | P19: S | Q19: Roma is a combination of a classic chenille texture design with a special padded backing to give a very soft, plush effect. The padded backing increases the durability of this 100% polyester fabric. The woven face creates a subtle color effect.
A20: C1584 | B20: Saxon | C20: 97 = Marine 31 = Oyster 48 = Chestnut 50 = Onyx 87 = Indigo | D20: 6 | E20: MU | F20: 43191 | G20: 14.4 | H20: 13.4 | I20: DR | J20: 100% Polyester | L20: N | P20: WS | Q20: Juxtapose this modern design with highly decorative and artful furnishings for a vibrant look. Pops of bold color let bright hues take center stage. The meticulously designed shapes, elegantly proportioned, are etched in full-faced plush chenille.
A21: C1625 | B21: Vance | C21: 32 = Sand 27 = Sage 86 = Eclipse 52 = Ice 76 = Mocha 08 = Garnet | D21: 6 | E21: CH | F21: 43374 | G21: 23.6 | H21: 24.4 | I21: UR | J21: 100% Polyester | L21: N | P21: WS | Q21: A multidimensional print on a textured, knit base cloth, Vance gives the illusion of a chunky woven, while maintaining the durability and plush feeling of a velvet.
A22: C1659 | B22: McKittrick | C22: 67 = Charcoal 72 = Taupe 62 = Smoke 86 = Indigo 92 = Mist | D22: 5 | E22: MU | F22: 43556 | G22: 0.3 | H22: 0.2 | I22: DR | J22: 100% Polyester | L22: N | P22: W
A23: C1670 | B23: Northern Exposure | C23: 76 = Daybreak | D23: 1 | E23: MU | F23: 43556 | G23: 14.37 | H23: 26.93 | I23: DR | J23: 100% Polyester | L23: N | P23: W | Q23: Enter the great outdoors with this detailed, woven tapestry pattern. Bring the wildlife into your home with deer, bears, and moose to give that rustic appeal.
A24: C1700 | B24: Nico | C24: 53 = Ash 57 = Charcoal 33 = Oyster | D24: 3 | E24: MU | F24: 43739 | G24: 0 | H24: 0 | I24: DR | J24: 95.5% Polyester, 4.5% Cotton | L24: N | N24: X | P24: S | Q24: Nico is a beautiful, traditional basket weave design incorporating novelty yarns in both the warp and fill directions for added dimension of color and texture in a classic pattern.
A25: C1754 | B25: Kemet | C25: 32 = Sand 74 = Brownstone 86 = Slate | D25: 3 | E25: MU | F25: 43922 | G25: 0 | H25: 0 | I25: UR | J25: 100% Polyester | L25: P | P25: S | Q25: This is a printed warp knit with an extremely soft hand. The print gives a subtle textured look to create more character on the face. All colors are very applicable for motion and recliners, as well casual stationary frames.
A26: C1757 | B26: Bartaloni | C26: 73 = Twig 33 = Birch 53 = Flannel 31 = Oatmeal | D26: 4 | E26: MU | F26: 43922 | G26: .625 | H26: 1.875 | I26: DR | J26: 100% Polyester | L26: N | P26: S | Q26: Bartaloni is a plush chenille with a fine herringbone pattern colored to live casually in todays’ interiors. Soft to the touch, beautiful and durable for our daily lives, Bartaloni is a great choice for any interior.
A27: C1809 | B27: Donegal | C27: 64 = Linen 69 = Granite 74 = Mushroom 87 = Marine | D27: 4 | E27: MU | F27: 44287 | G27: 0 | H27: 0 | I27: DR | J27: 100% Polyester | L27: N | P27: S | Q27: Pattern Donegal brings fashion to the forefront in your home where traditions start, and everyone is welcome. This bold plain assimilates inspiration from the runways of Paris, London, and Milan. A plain fabric seems like the simplest of textiles, but what goes into the creation of a great plain is really quite complicated. Beauty radiates warmth from the inspired mix of color and texture in pattern Donegal. Plush chenille is the yarn that creates a lofty feel and luxurious soft hand combined into an intricate dimensional plain weave. Donegal is alluring on its own offering exciting new colors each dreamy, natural, and calming. Live well with this chic and casual cover.
A28: C1812 | B28: Damon | C28: 33 = Oyster 54 = Stone 57 = Charcoal 62 = Muslin 86 = Midnight | D28: 5 | E28: MU | F28: 44287 | G28: 0 | H28: 0 | I28: UR | J28: 94% Polyester, 6% Nylon | L28: N | P28: S | Q28: Damon is a super soft padded piece-dyed chenille fabric with a fleece backing meant to accentuate the loft of the face. The fabric consists of a novelty subtle contrast yarn that is meant to give the product a bit more depth.
A29: C1852 | B29: Tiago | C29: 65 = Fawn 55 = Granite 52 = Twilight 76 = Mocha 86 = Navy | D29: 5 | E29: MU | F29: 44470 | G29: 0 | H29: 0 | I29: DR | J29: 100% Polyester | L29: N | P29: W | Q29: Create an environment of warmth and coziness with this soft chenille body cloth Tiago. Its space dyed warp yarns combined with a textured weave effect add depth and dimension to the bi-color chenille body. This gorgeous pattern will bring texture into the home. Offered in a selection of colors – Fawn, Granite, Mocha, Twilight and Navy you will find the right color to create a welcoming space. Tiago is made of 100% polyester and is exceeds over 15,000 double rubs.
A30: C1860 | B30: Persia | C30: 36 = Desert 86 = Lake 08 = Wine 54 = Greystone 76 = Bark | D30: 5 | E30: MU | F30: 44470 | G30: 0 | H30: 0 | I30: DR | J30: 100% Polyester | L30: N | P30: WS | Q30: An exceptionally soft face chenille semi-plain, Persia has both strength and durability because it is rated as a heavy duty wearable fabric. Persia is backed with a padding to give it a more substantial feel, making it perfect for motion applications. With its tonal shades of today’s popular colorations, combined with its soft hand, Persia also is a very saleable stationary cover.
A31: C1861 | B31: Sarah | C31: 86 = Indigo 58 = Slate 53 = Dove 62 = Truffle | D31: 4 | E31: MU | F31: 44652 | G31: 0 | H31: 0 | I31: DR | J31: 100% Polyester | L31: P | O31: X | P31: WS | Q31: a beautifully refined base cloth woven with a sumptuous high-quality chenille yarn on a finely, textured warp. The special warp creates a soft weave interest and enhanced durability.
A32: C1872 | B32: Lynx | C32: 33 = Burlap 76 = Birch 52 = Cement 32 = Cream | D32: 4 | E32: MU | F32: 44652 | G32: 0 | H32: 0 | I32: DR | J32: 100% Polyester | L32: N | P32: WS | Q32: Lynx is a 100% polyester jacquard, woven in tonal coloration combo’s. The mid-sized scaled pattern effect is subtle enough to be used on the body of any stationary group, but also distinctive enough to be used as an accent chair and pillow. A great value for a jacquard weave, Lynx rates as a heavy duty wearable fabric so it is perfect for motion.
A33: C1882 | B33: Lukas | C33: 32 = Khaki 86 = Navy 79 = Fudge 73 = Camel | D33: 4 | E33: MU | F33: 44652 | G33: 0 | H33: 0 | I33: DR | J33: 100% Polyester | L33: P | P33: S | Q33: Lukas is a tremendous fabric, perfect for motion. It is 100% polyester, heavy duty wearable, but with a luxuriously soft hand. Woven in a subtle, semi-plain block pattern, with a come and go strie twist yarn, the texture behind the plushness adds great eye appeal to the soft touch of LUKAS.
A34: C1945 | B34: Cordance | C34: 33=Pearl 54=Pebble 72=Driftwood 77=Chocolate | D34: 4 | E34: MU | F34: 45017 | G34: 0 | H34: 0 | I34: UR | J34: 100% Polyester | L34: N | P34: W | Q34: Cordance T/W is a unique texture with a distinctively vertical raised tufted cords also known as wales. This wide wale pattern, Cordance TW, has a soft hand and is the ideal fabric to make any piece of furniture extra cozy. Inherently plush, Cordance T/W is offered in four luscious colors: Chocolate, Driftwood, Pearl, and Pebble. Cordance T/W is made of 100% polyester.
A35: C1965 | B35: Nora | C35: 32=Ivory 52=Oyster 66=Truffle 84=Harbor | D35: 4 | E35: MU | F35: 45017 | G35: 0 | H35: 0 | I35: DR | J35: 100% Polyester | L35: N | P35: WS | Q35: A highly creative mix of soft chenille yarns woven with a variety of high and low novelty yarns define this multi textured base cloth. The combination of yarns and gentle interplay of color creates a wonderful surface interest base cloth that is highly usable for a wide variety of interior schemes.
A36: C1967 | B36: Lunar | C36: 33=Stone 55=Smoke 64=Taupe 68=Mocha 86=Navy | D36: 5 | E36: MU | F36: 45017 | G36: 0 | H36: 0 | I36: DR | J36: 97% Polyester, 3% Rayon | L36: P | P36: WS | Q36: A mélange woven chenille with a colorful warp creating a detailed background with a tweedy look & soft handle. It gives a luxurious feeling and looks extremely soft. This also enhances the seating comfort.
A37: C2029 | B37: Easy | C37: 07 = Brick 31 = Linen 58 = Stone 64 = Pebble 87 = Midnight | D37: 5 | E37: MU | F37: 45383 | G37: 0 | H37: 0 | I37: DR | J37: 100% Polyester | L37: N | P37: WS | Q37: Easy is a motion-friendly base cloth using multi-dimensional chenille in a high-low weave design. It has been paired with a padded, embossed backing for added visual dimension and texture in upholstery.
A38: C2032 | B38: Reyson | C38: 60 = Sand 64 = Taupe 74 = Sepia 78 = Bark 85 = Ocean | D38: 5 | E38: CH | F38: 45566 | G38: 0 | H38: 0 | I38: DR | J38: 100% Polyester | L38: N | P38: W | Q38: Reyson, a motion-friendly chenille, draws inspiration from the world of menswear and blending it with the comforting touch of chenille yarn. Its distinct weave pattern enhances the overall appeal, making it a compelling choice; combining style and affordability.
A39: C2035 | B39: Thane | C39: 31 = Linen 54 = Smoke 57 = Charcoal 78 = Chocolate | D39: 4 | E39: CH | F39: 45566 | G39: 0 | H39: 0 | I39: UR | J39: 100% Polyester | L39: P | P39: WS | Q39: Thane, is an irresistibly soft and plush printed knit base fabric. This medium pile construction delivers an unparalleled combination of comfort and performance like no other in the assortment.
A40: C2037 | B40: Tennant | C40: 51 = Porcelain 62 = Ceramic 66 = Mushroom 75 = Chestnut 78 = Otter | D40: 5 | E40: CH | F40: 45383 | G40: 0 | H40: 0 | I40: BU | J40: 100% Polyester | L40: P | P40: W | Q40: Tennant is a woven micro-denier base cloth that is extremely durable and soft. It is printed with natural leather imaging to give this new performance construction the look of hand rubbed leather.
A41: C2042 | B41: Duffey | C41: 32 = Oat 53 = Fog 60 = Dove 74 = Hazel | D41: 4 | E41: CH | F41: 45566 | G41: 0 | H41: 0 | I41: DR | J41: 100% Polyester | L41: N | P41: W | Q41: Duffy is a dobby woven fabric made with tonal, cationic textured yarns. Its small-scale weave offers subtle visual interest and a soft, yet smooth hand. The tonal coloring ensures easy coordination with other fabrics.
A42: C2043 | B42: Sheldon | C42: 57 = Granite 73 = Fawn 76 = Stone | D42: 3 | E42: CH | F42: 45566 | G42: 0 | H42: 0 | I42: DR | J42: 100% Polyester | L42: N | P42: WS | Q42: An ageless dobby woven base for all lifestyles. Created with beautiful heathered yarns and woven on a solid cotton-like dobby warp. Sheldon is a classic and very soft fabric for everyday living.
...

Sheet MASTER LEATHER
A1: All Active Leather SKU's as of April 2026 Market
A3: Leather Descriptions/Dot | K3: Product Line | Q3: Specialty Leather Descriptions
A4: Autentic (Tan) | B4: = A Pure, transparent dyes enhance natural markings such as wrinkles, scars and brands in each Authentic or Aniline hide. The dramatic color variations created are prized as hallmarks of quality and give each piece a distinctive look all its own. All Authentic leathers have a special protective topcoat that maintains the beauty and integrity of the natural characteristics of the hide. | K4: Select Leather Reclining | L4: = SLR Married leather with urethane/vinyl match on specific motion frames (Previously Select Motion) | Q4: A = Antimicrobial
Q5: C = Crypton
K6: Select Leather Stationary | L6: = SLS Maried leather with urethane/vinyl match on specific stationary frames (Previously Select Stationary) | Q6: I = iClean
Q8: Pillow Program
A9: Performance (Teal) | B9: =P The consistent overall color and subtle markings of Performance or protected leathers are created by a variety of techniques, such as embossing, corrective techniques and protective coatings, to improve resistance to soil and enhance their natural beauty. | K9: Custom Leather Match | L9: = CLM Custom Leather with urethane match available on select frames (Previously Custom Leather) | Q9: Pillows are NOT available in LL, LS, LM, RL, BU or UE cap codes
K11: Custom Leather Plus | L11: = CLP Custom Leather available on most frames | Q11: Key:
K12: Specialty Leather | L12: = SL Specialty Leather collection - Antimicrobial, Aniline and iClean | Q12: Immediate Drop
A13: Nubuck (Blue) | B13: =N Nubuck leathers are infused with pure, transparent dyes to give them subtle color variations without masking the natural character of the hide such as wrinkles, scars, brands, and other hallmarks of the trail. The result is a unique beauty that’s perfectly at home with today’s way of living. | Q13: Phase Outs
Q14: New Phase Outs
Q15: April 2026 Drops
A17: Series Number | B17: Pattern Name | C17: Product Line | D17: Intro Date | E17: Colors | F17: P/S=Postage Stamp, 12x12 | H17: Leather Description/ Dot | J17: Specialty Leather | K17: Cleaning Code | L17: Married Style(s) | O17: Notes | R17: Description(s)
A18: FL1907 | B18: Aline | C18: SL | D18: 44652 | E18: 54 = Light Grey 36 = Stonewash 84 = Haze 87 = Dark Blue 58 = Storm 77 = Chocolate | F18: 12x12, P/S | H18: A | J18: A | K18: L | R18: These semi-aniline hides are aniline dyed and then finished with a special feel agent added in the retannage to give the hides a superior touch. Because the feel agent is in the retannage it will not wear off over time. Special Effect: Along with the luxurious touch of Aline, a subtle two tone is added in the end to add to the visual depth and interest of this leather. The color pallet ranges from traditional colors to transitional to contemporary giving this article universal appeal across all types of styles. This tannage also provides an antimicrobial element due to special finishing. Please reference the marketing portion of our cover presentation for more detail!
A19: HL1906 | B19: Ankur | C19: SL | D19: 44652 | E19: 77 = Brown 73 = Oak 75 = Saddle 79 = Walnut | F19: 12x12, P/S | H19: A | J19: A | K19: L | R19: The dyeing process for Ankur is carried out in drums by means of aniline colorants which ensure a very high degree of light-fastness. High quality fats are used to maintain and enhance the natural softness of the hide. The hand of Ankur is achieved through a specific type of re-tanning with a long period of drum milling. Special Effect: After finishing, a special effect roller adds a two tone effect that simulates a genuine hand rubbed effect to the leather. This tannage also provides an antimicrobial element due to special finishing. Please reference the marketing portion of our cover presentation for more detail!
A20: FL1932 | B20: Athena | C20: SL | D20: 44835 | E20: 77 = Brown 63 = Ash 08 = Burgundy 55 = Grey 84 = Granite Grey 73 = Oak 59 = Carbon | F20: 12x12, P/S | H20: P | J20: I | K20: L | R20: Athena is elegant and sophisticated and has a soft fit that adapts very well to luxury furniture, with an uncluttered but rustic appearance. Athena brings an unprecedented softness using waxy technology. The more apparent grooves allow greater contrast between low and high relief, bringing a special shine. Being the first iClean™ leather, your environment will be luxurious and protected with Athena.
A21: DL2130 | B21: Atlantis | C21: CLP | D21: 46113 | E21: 86 = Marine 59 = Ash 73 = Russet 77 = Dark Brown | F21: P/S | H21: A | K21: L | R21: Atlantis is a 0.9–1.1mm semi-aniline leather featuring a natural grain with a light emboss. Its subtle two-tone effect and creamy hand create a refined surface with a rich, full-bodied feel. Atlantis brings together the heritage of leather with performance suited for modern living.
A22: LB2136 | B22: Bellingham | C22: SLR | D22: 46113 | E22: 79 = Moreno 59 = Coal | F22: 12x12 | H22: A | K22: L | L22: 826 Sammy | R22: A semi-aniline leather, Bellingham has a smooth, supple hand and refined medium sheen. At 1.0–1.2mm thickness, it showcases natural grain variation, while a subtle two-tone effect adds depth to the surface. The result is a polished, authentic leather with timeless character.
A23: LB1851 | B23: Camaraderie | C23: SLR | D23: 44652 | E23: 58 = Pewter 75 = Oak | F23: 12x12 | H23: P | K23: L | L23: 781 Emmons | R23: Comaraderie is a pigmented leather with a two tone sauvage effect and thickness of 1.0-1.2MM. This tannage features a very soft hand and excellent clarity in the finish.
A24: LB2141 | B24: Chic | C24: SLR | D24: 46113 | E24: 76 = Pecan 59 = Slate | F24: 12x12 | H24: A | K24: L | L24: A86 Ovation | R24: This semi-aniline leather features a natural grain with a distinctive oil pull-up effect, revealing beautiful highs and lows that create striking tonal movement. At 1.0–1.2mm thick with a fully protected finish, it offers lasting durability while maintaining a soft, supple hand. The result is a rich, dimensional leather that delivers elevated depth with a clean, contemporary edge.
A25: LB2062 | B25: Clifton | C25: SLR | D25: 45566 | E25: 19 = Chestnut 29 = Olive 78 = Walnut 79 = Dark Chocolate | F25: 12x12 | H25: A | K25: L | L25: 582 Maverick - Colors 78 & 79 717 Fulton - Colors 78 & 79 802 Cassian - Colors 78 & 79 810 Quinault - Colors 19 & 29 | R25: This article is a semi aniline with a natural grain and a thickness of 1.0-1.2mm. Clifton, hand rubbed at the tannery, it’s two-tone is rich in both color and depth and has medium sheen.
A26: BL9810 | B26: Cozy Match | C26: CLM | D26: 43922 | E26: 07 = Wine 09 = Pomegranate 31 = Oyster 36 = Marshmallow 50 = Licorice 51 = Dusty 54 = Putty 56 = Grey 76 = Walnut 78 = Tobacco 87 = Blueberry 90 = Seafoam 98 = Arctic Blue | F26: P/S | H26: P | K26: L | R26: Cozy Match is a soft, transparent, protected leather with a subtle two-tone effect that enhances the look of the color giving it depth and clarity.
A27: LB1590 | B27: Cranbrook | C27: SLR | D27: 43191 | E27: 58 = Shitake 79 = Chestnut | F27: 12x12 | H27: A | K27: L | L27: 519 Astor - Colors 58 & 79 | R27: Cranbrook is a semi-aniline dyed leather presenting a natural pebble grain appearance while showcasing a distinctive depth and clarity of color. Due to the higher quality of rawhide selection and supple characteristics, as well as a heavier gauge hand, this article of leather tailors extremely well.
A28: LB2063 | B28: Dean | C28: SLR | D28: 45566 | E28: 76 = Chestnut 79 = Shitake | F28: 12x12 | H28: A | K28: L | L28: 782 Kells 811 Acadia | O28: 811 - HG Top Stitching | R28: A semi-aniline, natural grain leather, Dean, has a thickness of 1.0-1.2mm providing nice drape and a soft, supple hand. Additionally, the leather is finished with a subtle, two-tone effect and an understated sheen in the topcoat.
A29: LB2063 | B29: Dean | C29: SLR | D29: 45767 | E29: 32 = Oyster 57 = Blue Grey 77 = Walnut | F29: 12x12 | H29: A | K29: L | L29: 800 Palmer 820 Norton | R29: A semi-aniline, natural grain leather, Dean, has a thickness of 1.0-1.2mm providing nice drape and a soft, supple hand. Additionally, the leather is finished with a subtle, two-tone effect and an understated sheen in the topcoat.
A30: LB1601 | B30: Delray | C30: SLR | D30: 43556 | E30: 75 = Harvest 79 = Dark Chocolate | F30: 12x12 | H30: A | K30: L | L30: 777 Randell | R30: Delray is the semi-aniline leather with natural grain and true hand-rub look. It has a very good hand and depth of color. The thickness of the leather is 1.0-1.2mm.
A31: LB1804 | B31: Elite | C31: SLR | D31: 44287 | E31: 74 = Cognac 59 = Charcoal 32 = Ice | F31: 12x12 | H31: P | K31: L | L31: 787 Lennon Recliner - Colors 32 & 59 762 Neo - Colors 59 & 74 | O31: 762 Neo - HG Top Stitching | R31: A beautiful semi aniline natural grain leather with a thickness of 1.1 – 1.2mm and slight savauge effects. This article has a super soft hand and normal sheen.
A32: LB2061 | B32: Gambit | C32: SLR | D32: 45566 | E32: 32 = Oyster 50 = Onyx 59 = Graphite 75 = Stone 78 = Otter | F32: 12x12 | H32: A | K32: L | L32: 747 Finley - Colors 50, 75 & 78 765 Rowan - Colors 32, 59 & 78 803 Cade - Colors 32 & 75 | R32: Gambit is a full-bodied semi-aniline with a medium grain and a thickness of 1.2-1.4mm. This article has a buttery, soft hand and is a semi-matte look with a gentle two-tone effect
A33: LB1728 | B33: Goshen | C33: SLR | D33: 43922 | E33: 56 = Grey 78 = Chestnut | F33: 12x12 | H33: A | K33: L | L33: 502 Joshua | O33: Comes standard with single-needle topstitching on the arms. | R33: Goshen features a two-tone color effect with a soft and waxy appearance, using a corrected grain, being as close as possible to semi aniline. The hand, feel and softness make this a comfortable and luxurious leather.
A34: FL1963 | B34: Gramado | C34: CLP | D34: 45017 | E34: 57 = Coal 73 = Russet 76 = Cedar 79 = Coffee | F34: P/S | H34: A | K34: L | O34: ```````` | R34: Transitional/Traditional This classic Semi-Aniline leather hits all the high notes – it’s creamy soft and smooth with an understated natural grain and a popular two-tone kela effect. With deep rich colors and a medium sheen that adds brightness and radiance, Gramado is elegant and versatile. It works well with any type of furniture including motion and recliners and has been designed for active households. Color palette/special texture Available in classic shades, Gramado features a subtle natural grain and soft, creamy hand. Natural markings have been minimized but will remain visible. Techno facts Hides are selected, cut thinner, and then tanned and dyed using state-of-the-art methods. Hides are lightly corrected, colored, and then overprinted with a kela effect. Then hides are embossed with a natural grain. A medium sheen topcoat is applied to finish the look and help resist everyday stains and spills.
A35: FL2026/LB2026 | B35: Grandview | C35: CLP SLR | D35: 45383 | E35: 51 = Dove Grey 59 = Otter 75 = Chestnut 98 = Ocean | F35: P/S, 12x12 | H35: A | K35: L | L35: 712 Sparrow - Colors 51, 59 & 75 | O35: Custom Leather - all colors Select Reclining - 51, 59 & 75 | R35: A semi-aniline natural grain leather, rich in color, with a distinct matte finish and sueded hand which emulates that of a nubuck. Grandview is drum dyed, buffed, milled, ironed and protected with a topcoat to preserve the look, hand and color of the article.
A36: FL1523 | B36: Great Smokies | C36: CLP | D36: 42826 | E36: 52 = Tin 57 = Smoke 73 = Gingerbread 75 = Pecan 79 = Chocolate | F36: P/S | H36: A | K36: L | R36: Great Smokies is corrected and embossed, with a waxy, soft hand. The slight crackled finish is achieved by tumbling, and the visual depth and two-tone coloration are courtesy of roller-coating. A medium-sheen topcoat finishes the look and helps protect against everyday stains and spills. Finally, hides are hot ironed for smoothness.
A37: LB2112 | B37: Highbrow | C37: SLR | D37: 45931 | E37: 75 = Mocha 78 = Mineral 58 = Blue Grey | F37: 12x12 | H37: A | K37: L | L37: 755 Dorian - Colors 75 & 78 807 Baron - Colors 58, 75 & 78 | O37: 807 Baron - HG Top Stitching | R37: Highbrow, a semi-aniline embodies timeless luxury. Showcasing a natural grain to hightlight the authentic beauty of the hide, the article has a luxuriously soft hand, exceptional drtage with just the right touch of sheen. A 1.1-1.3MM thickness ensures durability without sacrificing elegance.
A38: LB2112 | B38: Highbrow | C38: SLR | D38: 46113 | E38: 76 = Chestnut 68 = Slate | F38: 12x12 | H38: A | K38: L | L38: 757 Apollo - Colors 68 & 76 | O38: 757 Apollo - Decorative HG Top Stitching | R38: Highbrow, a semi-aniline embodies timeless luxury. Showcasing a natural grain to hightlight the authentic beauty of the hide, the article has a luxuriously soft hand, exceptional drtage with just the right touch of sheen. A 1.1-1.3MM thickness ensures durability without sacrificing elegance.
A39: LB1727 | B39: Intermingle | C39: SLR | D39: 43922 | E39: 55 = Grey 79 = Walnut | F39: 12x12 | H39: A | K39: L | L39: 724 Trouper | O39: Comes standard with tonal heavy-gauge single-needle topstitching on the arms, backs, chaises and footrests. | R39: Intermingle is semi-aniline leather, which is very slightly corrected and embossed. The printing, spraying, tipping and tumbling processes are used to achieve the look, color, hand and depth.
A40: DL1962 | B40: Jazz | C40: SL | D40: 45017 | E40: 36=Moonbeam 58=Charcoal 75=Cinnamon 78=Coffee 86=Midnight Blue | F40: 12x12, P/S | H40: P | J40: I | K40: L
A41: FL2003 | B41: Jesi | C41: CLP | D41: 45200 | E41: 07 = Rouge 59 = Otter 63 = Stone 72 = Barley 75 = Khaki 77 = Sepia | F41: P/S | H41: A | K41: L | R41: A semi-aniline, Jesi, has a timeless, natural aesthetic with subtle two-tone aniline-like characteristics that are created through innovative finishing techniques and rounded out with a soft, supple hand.
A42: LB1849 | B42: Lota | C42: SLR | D42: 44470 | E42: 64 = Pebble 78 = Espresso | F42: 12x12 | H42: P | K42: L | L42: LB1849 Lota on 786 Liam Recliner - Phase Out LB1849 Lota on 786 Liam Motion - Dropped | R42: Lota is a soft pigmented performance leather that is perfect for relaxing. The overall even surface of the leather, along with the clean, saturated colors, create an appealing high-end leather look.
A43: FL2078 | B43: Manchester | C43: SL | D43: 45767 | E43: 25 = Olive 29 = Envy 31 = Ivory 49 = Tan 76 = Toffee 86 = Midnight | F43: 12x12, P/S | H43: A | J43: I | K43: L | R43: Manchester features a stippled grain that mimics the look of antiqued leather, while its water-based finish adds protection and a subtle sheen. Offering the aesthetics of wax pull-up leather without the high price or finish sensitivity, this semi-aniline leather is protected with i-Clean® technology, ensuring resistance to liquids and stains for up to three years.
A44: BL2117 | B44: Majestic Match | C44: CLM | D44: 46113 | E44: 73 = Butternut 78 = Chocolate 58 = Coal 86 = Blue 63 = Stonewash | F44: P/S | H44: A | K44: L | R44: With a 1.2-1.4mm thickness, Majestic is a high-performance semi-aniline leather that delivers the depth and richness of an aniline look with a soft, wet hand feel. The distinctive savage kella effect creates two-tone variation and natural movement, finished in a refined semi-matte top-coat.
...

Sheet Dealer Swatch Inventory
A1: Cover | B1: Design Center (Large) | C1: Comfort Studio (Small) | D1: Ring Page | E1: Custom DC Single Swatch ONLY | F1: Cover Name | G1: Color Name | H1: Status
A2: B153808 | B2: X | C2: X | D2: X | F2: SEAMOUNT | G2: BURGUNDY | H2: ACTIVE
A3: B153853 | B3: X | C3: X | D3: X | F3: SEAMOUNT | G3: SILVER | H3: ACTIVE
A4: B153874 | B4: X | C4: X | D4: X | F4: SEAMOUNT | G4: SABLE | H4: ACTIVE
A5: B153876 | B5: X | C5: X | D5: X | F5: SEAMOUNT | G5: CAPPUCCINO | H5: ACTIVE
A6: B153885 | B6: X | C6: X | D6: X | F6: SEAMOUNT | G6: INDIGO | H6: ACTIVE
A7: B166257 | B7: X | C7: X | D7: X | F7: RODIGO | G7: STONE | H7: DROPPED
A8: B166276 | B8: X | C8: X | D8: X | F8: RODIGO | G8: MARSH | H8: DROPPED
A9: B166278 | B9: X | C9: X | D9: X | F9: RODIGO | G9: WALNUT | H9: DROPPED
A10: B166286 | B10: X | C10: X | D10: X | F10: RODIGO | G10: NAVY | H10: DROPPED
A11: B180852 | B11: X | C11: X | D11: X | F11: SOCIAL CLUB | G11: STONE | H11: ACTIVE
A12: B180857 | B12: X | C12: X | D12: X | F12: SOCIAL CLUB | G12: CHARCOAL | H12: ACTIVE
A13: B180868 | B13: X | C13: X | D13: X | F13: SOCIAL CLUB | G13: PEWTER | H13: ACTIVE
... A15: B180876 | B15: X | C15: X | D15: X | F15: SOCIAL CLUB | G15: COCOA | H15: ACTIVE
A16: B182725 | B16: X | D16: X | F16: BRINK | G16: LENTIL | H16: DROPPED
A17: B182786 | B17: X | D17: X | F17: BRINK | G17: SLATE | H17: ACTIVE
A18: BL211758 | D18: X | F18: MAJESTIC MATCH | G18: COAL | H18: ACTIVE
A19: BL211763 | D19: X | F19: MAJESTIC MATCH | G19: STONEWASH | H19: ACTIVE
A20: BL211773 | D20: X | F20: MAJESTIC MATCH | G20: BUTTERNUT | H20: ACTIVE
A21: BL211778 | D21: X | F21: MAJESTIC MATCH | G21: CHOCOLATE | H21: ACTIVE
A22: BL211786 | D22: X | F22: MAJESTIC MATCH | G22: BLUE | H22: ACTIVE
A23: BL981007 | D23: X | F23: COZY MATCH | G23: WINE | H23: ACTIVE
A24: BL981009 | D24: X | F24: COZY MATCH | G24: POMEGRANATE | H24: ACTIVE
A25: BL981031 | D25: X | F25: COZY MATCH | G25: OYSTER | H25: ACTIVE
A26: BL981036 | D26: X | F26: COZY MATCH | G26: MARSHMALLOW | H26: ACTIVE
A27: BL981050 | D27: X | F27: COZY MATCH | G27: LICORICE | H27: ACTIVE
A28: BL981051 | D28: X | F28: COZY MATCH | G28: DUSTY | H28: ACTIVE
A29: BL981054 | D29: X | F29: COZY MATCH | G29: PUTTY | H29: ACTIVE
... A35: BL981098 | D35: X | F35: COZY MATCH | G35: ARCTIC BLUE | H35: ACTIVE
A36: C137108 | B36: X | C36: X | D36: X | F36: SEASONS | G36: REDWOOD | H36: DROPPED
A37: C137128 | B37: X | C37: X | D37: X | F37: SEASONS | G37: LODEN | H37: DROPPED
A38: C137162 | B38: X | C38: X | D38: X | F38: SEASONS | G38: KHAKI | H38: DROPPED
A39: C137166 | B39: X | C39: X | D39: X | F39: SEASONS | G39: MOCHA | H39: DROPPED
A40: C137178 | B40: X | C40: X | D40: X | F40: SEASONS | G40: CHOCOLATE | H40: DROPPED
A41: C137187 | B41: X | C41: X | D41: X | F41: SEASONS | G41: CHARCOAL | H41: DROPPED
A42: C151631 | B42: X | D42: X | F42: MERIT | G42: DOVE | H42: DROPPED
A43: C151651 | B43: X | D43: X | F43: MERIT | G43: PLATINUM | H43: DROPPED
A44: C151657 | B44: X | D44: X | F44: MERIT | G44: CHARCOAL | H44: DROPPED
A45: C152534 | B45: X | C45: X | D45: X | F45: ROMA | G45: CREAM | H45: ACTIVE
A46: C152553 | B46: X | C46: X | D46: X | F46: ROMA | G46: STORM | H46: ACTIVE
...

Sheet Ring Pages - Complete Set
A1: The following swatches for the La-Z-Boy Major Upholstery Collection represent current offerings as of the April 2026 Market.
A2: MU | K2: Key:
K3: Immediate Drop
B4: **NOTE** Merchandising suggests that ring pages be replaced every three years for color accuracy. Replacement Swatches can be ordered through EPI. | K4: Phase Outs
K5: New Phase Outs
K6: April 2026 Drops
A8: Item Number | B8: Intro Date | C8: Date Last Updated | D8: S=Single, C=Correlate, W/F=Waterfall, P/S=Postage Stamp | E8: Pattern Name | F8: Cover1 | G8: Cover2 | H8: Cover3 | I8: Cover4 | J8: Cover5 | K8: Cover6 | L8: Cover7
A9: SCPZB153876 | B9: 43009 | D9: P/S | E9: Seamount | F9: B153876 | G9: B153874 | H9: B153808 | I9: B153853 | J9: B153885
A10: SCPZC152553 | B10: 42826 | D10: P/S | E10: Roma | F10: C152553 | G10: C152578 | H10: C152574 | I10: C152586 | J10: C152534
A11: SCPZC162532 | B11: 43374 | D11: P/S | E11: Vance | F11: C162532 | G11: C162527 | H11: C162586 | I11: C162552 | J11: C162576 | K11: C162508
A12: SCPZD156453 | B12: 43191 | C12: 44835 | D12: P/S | E12: i-Hallandale | F12: D156453 | G12: D156464 | H12: D156431 | I12: D156458 | J12: D156487
A13: SCPZD160462 | B13: 43374 | D13: P/S | E13: i-Outlier | F13: D160462 | G13: D160454 | H13: D160476 | I13: D160479 | J13: D160458
A14: SCPZD160662 | B14: 43374 | C14: 44835 | D14: P/S | E14: i-Halifax | F14: D160662 | G14: D160632 | H14: D160654 | I14: D160678 | J14: D160686
A15: SCPZD210765 | B15: 45931 | D15: P/S | E15: Westcott | F15: D210765 | G15: D210731 | H15: D210769 | I15: D210758
A16: SCPZE153755 | B16: 44835 | D16: P/S | E16: i-Northwest | F16: E153755 | G16: E153773 | H16: E153752
A17: SCPZE153767 | B17: 43009 | D17: P/S | E17: i-Northwest | F17: E153767 | G17: E153758 | H17: E153775 | I17: E153765 | J17: E153732
A18: SMPZB180857 | B18: 44287 | D18: P/S | E18: Social Club | F18: B180857 | G18: B180876 | H18: B180868 | I18: B180852 | J18: B180872
A19: SMPZB182786 | B19: 45931 | D19: P/S | E19: Brink | F19: B182786 | G19: B182725
A20: SMPZC158497 | B20: 43191 | C20: 45748 | D20: P/S | E20: Saxon | F20: C158497 | G20: C158448 | H20: C158431 | I20: C158450 | J20: C158487
A21: SMPZC170053 | B21: 43739 | C21: 44835 | D21: P/S | E21: Nico | F21: C170053 | G21: C170057 | H21: C170033
A22: SMPZC175432 | B22: 43922 | C22: 44835 | D22: P/S | E22: Kemet | F22: C175432 | G22: C175474 | H22: C175486
A23: SMPZC175773 | B23: 43922 | D23: P/S | E23: Bartaloni | F23: C175773 | G23: C175733 | H23: C175753 | I23: C175731
A24: SMPZC180974 | B24: 44287 | C24: 44835 | D24: P/S | E24: Donegal | F24: C180974 | G24: C180969 | H24: C180964 | I24: C180987
A25: SMPZC181257 | B25: 44287 | D25: P/S | E25: Damon | F25: C181257 | G25: C181233 | H25: C181286 | I25: C181254 | J25: C181262
A26: SMPZC185265 | B26: 44470 | D26: P/S | E26: Tiago | F26: C185265 | G26: C185255 | H26: C185252 | I26: C185276 | J26: C185286
A27: SMPZC186036 | B27: 44470 | D27: P/S | E27: Persia | F27: C186036 | G27: C186086 | H27: C186008 | I27: C186054 | J27: C186076
A28: SMPZC186186 | B28: 44652 | D28: P/S | E28: Sarah | F28: C186186 | G28: C186158 | H28: C186153 | I28: C186162
A29: SMPZC187233 | B29: 44652 | D29: P/S | E29: Lynx | F29: C187233 | G29: C187276 | H29: C187252 | I29: C187232
A30: SMPZC188232 | B30: 44652 | D30: P/S | E30: Lukas | F30: C188232 | G30: C188286 | H30: C188279 | I30: C188273
A31: SMPZC196584 | B31: 45017 | D31: P/S | E31: Nora | F31: C196584 | G31: C196552 | H31: C196566 | I31: C196532
A32: SMPZC196733A | B32: 45566 | D32: P/S | E32: Lunar | F32: C196733 | G32: C196764 | H32: C196768 | I32: C196755 | J32: C196786
A33: SMPZC202931 | B33: 45383 | D33: P/S | E33: Easy | F33: C202931 | G33: C202964 | H33: C202958 | I33: C202907 | J33: C202987
A34: SMPZC203264 | B34: 45566 | D34: P/S | E34: Reyson | F34: C203264 | G34: C203278 | H34: C203274 | I34: C203285 | J34: C203260
A35: SMPZC203531 | B35: 45566 | D35: P/S | E35: Thane | F35: C203531 | G35: C203578 | H35: C203557 | I35: C203554
A36: SMPZC204260 | B36: 45566 | D36: P/S | E36: Duffey | F36: C204260 | G36: C204232 | H36: C204274 | I36: C204253
A37: SMPZC204373 | B37: 45566 | D37: P/S | E37: Sheldon | F37: C204373 | G37: C204376 | H37: C204357
A38: SMPZC204953 | B38: 45566 | D38: P/S | E38: Julien | F38: C204953 | G38: C204948 | H38: C204954 | I38: C204918
A39: SMPZC205376 | B39: 45566 | D39: P/S | E39: Clarke | F39: C205376 | G39: C205314 | H39: C205387 | I39: C205329
A40: SMPZC205682 | B40: 45566 | D40: P/S | E40: Seattle | F40: C205682 | G40: C205615 | H40: C205631
A41: SMPZC206764 | B41: 45748 | D41: P/S | E41: Axe | F41: C206764 | G41: C206774 | H41: C206759 | I41: C206786
...

Sheet Design Center
A1: The following swatches for the La-Z-Boy Design Center Collection represent current offerings as of the April 2026 Market.
A2: DC | J2: Specialty Fabric Descriptions | M2: Key:
J3: I = iClean | M3: Immediate Drop
J4: C = Conserve | M4: Phase Outs
J5: A = Antimicrobial | M5: New Phase Outs
J6: PF = Pet Friendly | M6: April 2026 Drops
J7: N = Nanobionic
J8: W*B = Bleach Cleanable
A10: Item Number | B10: Intro Date | C10: Date Last Updated | D10: S=Single, C=Correlate, W/F=Waterfall | E10: Pattern Name | F10: Specialty Fabric | G10: Comfort Studio | H10: Custom DC Single Swatch ONLY | I10: Cover1 | J10: Cover2 | K10: Cover3 | L10: Cover4 | M10: Cover5 | N10: Cover6 | O10: Cover7 | P10: Color Names
A11: SDSZJ208802 | B11: 45748 | D11: S | E11: Faircrest | I11: J208802 | P11: Blush
A12: SDSZD169303 | B12: 45931 | D12: S | E12: Milo | I12: D169303 | P12: Mauve
A13: SDSZJ201705 | B13: 45383 | D13: S | E13: Haze | I13: J201705 | P13: Terracotta
A14: SDSZQ208705 | B14: 45748 | D14: S | E14: Liliana | I14: Q208705 | P14: Rouge
A15: SDSZD208606 | B15: 45748 | D15: S | E15: Spring Valley | G15: X | I15: D208606 | P15: Blossom
A16: SDCZD208606 | B16: 45748 | D16: C | E16: Spring Valley | I16: D208606 | J16: J208907 | K16: Q208705 | L16: D209009 | M16: J208802 | P16: Blossom/Papaya/Rouge/Crimson/Blush
A17: SDSZC202907 | B17: 45383 | D17: S | E17: Easy | G17: X | I17: C202907 | P17: Brick
A18: SDSZJ208907 | B18: 45748 | D18: S | E18: Josephine | I18: J208907 | P18: Papaya
A19: SDSZC162508 | B19: 43374 | D19: S | E19: Vance | G19: X | I19: C162508 | P19: Garnet
A20: SDSZC186008 | B20: 44470 | D20: S | E20: Persia | G20: X | I20: C186008 | P20: Wine
A21: SDSZE186608 | B21: 44652 | D21: S | E21: Vitani | I21: E186608 | P21: Brick
A22: SDSZJ213308 | B22: 46137 | D22: S | E22: McCoy | I22: J213308 | P22: Mauve
A23: SDSZJ213508 | B23: 46137 | D23: S | E23: Anisette | I23: J213508 | P23: Wine
A24: SDSZJ213808 | B24: 46137 | D24: S | E24: Cabana | I24: J213808 | P24: Chai
A25: SDSZD209009 | B25: 45748 | D25: S | E25: Penelope | I25: D209009 | P25: Crimson
A26: SDSZD209810 | B26: 45931 | D26: S | E26: Gabby | I26: D209810 | P26: Gold
A27: SDSZD210211 | B27: 45931 | D27: S | E27: Picasso | G27: X | I27: D210211 | P27: Desert
A28: SDSZD201612 | B28: 45383 | D28: S | E28: Coast | G28: X | I28: D201612 | P28: Coral
A29: SDSZD209712 | B29: 45931 | D29: S | E29: Donatello | I29: D209712 | P29: Canyon
A30: SDSZC205314 | B30: 45566 | D30: S | E30: Clarke | G30: X | I30: C205314 | P30: Blush
A31: SDSZD169314 | B31: 45931 | D31: S | E31: Milo | I31: D169314 | P31: Russet
A32: SDSZD201014 | B32: 45383 | D32: S | E32: i-Rene | F32: I | G32: X | I32: D201014 | P32: Nutmeg
A33: SDSZE182014 | B33: 44287 | D33: S | E33: Wheelie | G33: X | I33: E182014 | P33: Copper
A34: SDSZJ204814 | B34: 45566 | D34: S | E34: Montebello | I34: J204814 | P34: Cognac
A35: SDSZC205615 | B35: 45566 | D35: S | E35: Seattle | G35: X | I35: C205615 | P35: Brandy
A36: SDSZD149415 | B36: 42826 | D36: S | E36: Prospect | I36: D149415 | P36: Currant
A37: SDSZE176315 | B37: 43922 | D37: S | E37: i-Esma | F37: I, C, PF | I37: E176315 | P37: Autumn
A38: SDSZQ197715 | B38: 45931 | D38: S | E38: Tinsley | F38: W*B | I38: Q197715 | P38: Autumn
A39: SDSZD209716 | B39: 45931 | D39: S | E39: Donatello | I39: D209716 | P39: Harvest
A40: SDSZE182016 | B40: 44287 | D40: S | E40: Wheelie | G40: X | I40: E182016 | P40: Spice
A41: SDSZQ199616 | B41: 45200 | D41: S | E41: Alora | I41: Q199616 | P41: Spice
...

Sheet 6x6 Fabric
A1: The following swatches for the 6x6 Inline Customer Swatches represent current offerings as of the April 2026 Market.
A2: 6I
F3: Key:
F4: Immediate Drop
F5: Phase Outs
F6: New Phase Outs
F7: April 2026 Drops
A9: Item Number | B9: Intro Date | C9: Date Last Updated | D9: S=Single, C=Correlate, W/F=Waterfall, P/S=Postage Stamp | E9: Pattern Name | F9: Color Name | G9: Cover
A10: SC6ZB153808 | B10: =VLOOKUP(E10,'MASTER FABRICS'!B:F,5,FALSE) -> 43009 | D10: 6x6 | E10: Seamount | F10: Burgundy | G10: B153808
A11: SC6ZB153853 | B11: =VLOOKUP(E11,'MASTER FABRICS'!B:F,5,FALSE) -> 43009 | D11: 6x6 | E11: Seamount | F11: Silver | G11: B153853
A12: SC6ZB153874 | B12: =VLOOKUP(E12,'MASTER FABRICS'!B:F,5,FALSE) -> 43009 | D12: 6x6 | E12: Seamount | F12: Sable | G12: B153874
A13: SC6ZB153876 | B13: =VLOOKUP(E13,'MASTER FABRICS'!B:F,5,FALSE) -> 43009 | D13: 6x6 | E13: Seamount | F13: Cappuccino | G13: B153876
A14: SC6ZB153885 | B14: =VLOOKUP(E14,'MASTER FABRICS'!B:F,5,FALSE) -> 43009 | D14: 6x6 | E14: Seamount | F14: Indigo | G14: B153885
A15: SM6ZB180852 | B15: =VLOOKUP(E15,'MASTER FABRICS'!B:F,5,FALSE) -> 44287 | D15: 6x6 | E15: Social Club | F15: Stone | G15: B180852
A16: SM6ZB180857 | B16: =VLOOKUP(E16,'MASTER FABRICS'!B:F,5,FALSE) -> 44287 | D16: 6x6 | E16: Social Club | F16: Charcoal | G16: B180857
A17: SM6ZB180868 | B17: =VLOOKUP(E17,'MASTER FABRICS'!B:F,5,FALSE) -> 44287 | D17: 6x6 | E17: Social Club | F17: Pewter | G17: B180868
A18: SM6ZB180872 | B18: =VLOOKUP(E18,'MASTER FABRICS'!B:F,5,FALSE) -> 44287 | D18: 6x6 | E18: Social Club | F18: Chalk | G18: B180872
A19: SM6ZB180876 | B19: =VLOOKUP(E19,'MASTER FABRICS'!B:F,5,FALSE) -> 44287 | D19: 6x6 | E19: Social Club | F19: Cocoa | G19: B180876
A20: SD6ZB182786 | B20: =VLOOKUP(E20,'MASTER FABRICS'!B:F,5,FALSE) -> 44287 | D20: 6x6 | E20: Brink | F20: Slate | G20: B182786
A21: SC6ZC152534 | B21: =VLOOKUP(E21,'MASTER FABRICS'!B:F,5,FALSE) -> 42826 | D21: 6x6 | E21: Roma | F21: Cream | G21: C152534
... A81: SM6ZC196584 | B81: =VLOOKUP(E81,'MASTER FABRICS'!B:F,5,FALSE) -> 45017 | D81: 6x6 | E81: Nora | F81: Harbor | G81: C196584
A82: SM6ZC196733 | B82: 45017 | D82: 6x6 | E82: Lunar | F82: Stone | G82: C196733
A83: SM6ZC196755 | B83: 45017 | D83: 6x6 | E83: Lunar | F83: Smoke | G83: C196755
A84: SM6ZC196764 | B84: 45017 | D84: 6x6 | E84: Lunar | F84: Taupe | G84: C196764
A85: SM6ZC196768A | B85: 45017 | D85: 6x6 | E85: Lunar | F85: Mocha | G85: C196768
A86: SM6ZC196786A | B86: 45017 | D86: 6x6 | E86: Lunar | F86: Navy | G86: C196786
A87: SM6ZC202931 | B87: 45383 | D87: 6x6 | E87: Easy | F87: Linen | G87: C202931
A88: SM6ZC202964 | B88: 45383 | D88: 6x6 | E88: Easy | F88: Pebble | G88: C202964
A89: SM6ZC202958 | B89: 45383 | D89: 6x6 | E89: Easy | F89: Stone | G89: C202958
A90: SM6ZC202907 | B90: 45383 | D90: 6x6 | E90: Easy | F90: Brick | G90: C202907
A91: SM6ZC202987 | B91: 45383 | D91: 6x6 | E91: Easy | F91: Midnight | G91: C202987
A92: SM6ZC203260 | B92: 45566 | D92: 6x6 | E92: Reyson | F92: Sand | G92: C203260
A93: SM6ZC203264 | B93: 45566 | D93: 6x6 | E93: Reyson | F93: Taupe | G93: C203264
... A145: SM6ZC212267 | B145: 46113 | D145: 6x6 | E145: Taber | F145: Mushroom | G145: C212267
A146: SM6ZD149415 | B146: =VLOOKUP(E146,'MASTER FABRICS'!B:F,5,FALSE) -> 42826 | D146: 6x6 | E146: Prospect | F146: Currant | G146: D149415
A147: SM6ZD149452 | B147: =VLOOKUP(E147,'MASTER FABRICS'!B:F,5,FALSE) -> 42826 | D147: 6x6 | E147: Prospect | F147: Greystone | G147: D149452
A148: SM6ZD156431 | B148: =VLOOKUP(E148,'MASTER FABRICS'!B:F,5,FALSE) -> 43191 | D148: 6x6 | E148: i-Hallandale | F148: Ivory | G148: D156431
A149: SM6ZD156453 | B149: =VLOOKUP(E149,'MASTER FABRICS'!B:F,5,FALSE) -> 43191 | D149: 6x6 | E149: i-Hallandale | F149: Platinum | G149: D156453
A150: SM6ZD156458 | B150: =VLOOKUP(E150,'MASTER FABRICS'!B:F,5,FALSE) -> 43191 | D150: 6x6 | E150: i-Hallandale | F150: Charcoal | G150: D156458
A151: SM6ZD156464 | B151: =VLOOKUP(E151,'MASTER FABRICS'!B:F,5,FALSE) -> 43191 | D151: 6x6 | E151: i-Hallandale | F151: Wicker | G151: D156464
...

Sheet 3x5 Leather
A1: The following swatches for the 3x5 Inline Customer Swatches represent current offerings as of the April 2026 Market.
A2: 6C
F3: Key:
F4: Immediate Drop
F5: Phase Outs
F6: New Phase Outs
F7: April 2026 Drops
A9: Item Number | B9: Intro Date | C9: Date Last Updated | D9: S=Single, C=Correlate, W/F=Waterfall, P/S=Postage Stamp | E9: Pattern Name | F9: Color Name | G9: Cover
A10: SL6BL211758 | B10: 46137 | D10: 3x5 | E10: Majestic Match | F10: Coal | G10: BL211758
A11: SL6BL211763 | B11: 46137 | D11: 3x5 | E11: Majestic Match | F11: Stonewash | G11: BL211763
A12: SL6BL211773 | B12: 46137 | D12: 3x5 | E12: Majestic Match | F12: Butternut | G12: BL211773
A13: SL6BL211778 | B13: 46137 | D13: 3x5 | E13: Majestic Match | F13: Chocolate | G13: BL211778
A14: SL6BL211786 | B14: 46137 | D14: 3x5 | E14: Majestic Match | F14: Blue | G14: BL211786
A15: SL6BL981007 | B15: 43922 | D15: 3x5 | E15: Cozy Match | F15: Wine | G15: BL981007
A16: SL6BL981009 | B16: 43922 | D16: 3x5 | E16: Cozy Match | F16: Pomegranate | G16: BL981009
A17: SL6BL981031 | B17: 45383 | D17: 3x5 | E17: Cozy Match | F17: Oyster | G17: BL981031
A18: SL6BL981036 | B18: 43922 | D18: 3x5 | E18: Cozy Match | F18: Marshmallow | G18: BL981036
A19: SL6BL981050 | B19: 43922 | D19: 3x5 | E19: Cozy Match | F19: Licorice | G19: BL981050
A20: SL6BL981051 | B20: 43922 | D20: 3x5 | E20: Cozy Match | F20: Dusty | G20: BL981051
A21: SL6BL981054 | B21: 43922 | D21: 3x5 | E21: Cozy Match | F21: Putty | G21: BL981054
... A150: SL6LB214176 | B150: 46113 | D150: 3x5 | E150: Chic | F150: Pecan | G150: LB214176
A152: DROPPED
A153: SL6FL152352 | B153: 42826 | D153: 3x5 | E153: Great Smokies | F153: Tin | G153: FL152352
A154: SL6FL152357 | B154: 42826 | D154: 3x5 | E154: Great Smokies | F154: Smoke | G154: FL152357
A155: SL6FL152373 | B155: 42826 | D155: 3x5 | E155: Great Smokies | F155: Gingerbread | G155: FL152373
A156: SL6FL152375 | B156: 42826 | D156: 3x5 | E156: Great Smokies | F156: Pecan | G156: FL152375
A157: SL6FL152379 | B157: 42826 | D157: 3x5 | E157: Great Smokies | F157: Chocolate | G157: FL152379
A158: SL6FL196357 | B158: 45017 | D158: 3x5 | E158: Gramado | F158: Coal | G158: FL196357
A159: SL6FL196373 | B159: 45017 | D159: 3x5 | E159: Gramado | F159: Russet | G159: FL196373
A160: SL6FL196376 | B160: 45017 | D160: 3x5 | E160: Gramado | F160: Cedar | G160: FL196376
A161: SL6FL196379 | B161: 45017 | D161: 3x5 | E161: Gramado | F161: Coffee | G161: FL196379
A162: SL6FL941962 | B162: 44835 | D162: 3x5 | E162: Samba | F162: Clay | G162: FL941962
A163: SL6FL941942 | B163: 44835 | D163: 3x5 | E163: Samba | F163: Marigold | G163: FL941942
A164: SL6FL941908 | B164: 44835 | D164: 3x5 | E164: Samba | F164: Crimson | G164: FL941908
A165: SL6LB180432 | B165: 44652 | D165: 3x5 | E165: Elite | F165: Ice | G165: LB180432

Sheet 2x3 Leather
A1: The following swatches for the 2x3 Inline Customer Swatches represent current offerings as of the April 2026 Market.
A2: LR | F2: Key:
F3: Immediate Drop
A4: SC2 = Custom / Custom Plus | F4: Phase Outs
A5: SL2 = Specialty | F5: New Phase Outs
F6: April 2026 Drops
A8: Item Number 2x3 Swatch | B8: Intro Date | C8: Date Last Updated | D8: Line | E8: Pattern Name | F8: Color Name | G8: Cover1
A9: SC2BL211758 | B9: 46113 | D9: Custom | E9: Majestic Match | F9: Coal | G9: BL211758
A10: SC2BL211763 | B10: 46113 | D10: Custom | E10: Majestic Match | F10: Stonewash | G10: BL211763
A11: SC2BL211773 | B11: 46113 | D11: Custom | E11: Majestic Match | F11: Butternut | G11: BL211773
A12: SC2BL211778 | B12: 46113 | D12: Custom | E12: Majestic Match | F12: Chocolate | G12: BL211778
A13: SC2BL211786 | B13: 46113 | D13: Custom | E13: Majestic Match | F13: Blue | G13: BL211786
A14: SC2BL981007 | B14: 43922 | D14: Custom | E14: Cozy Match | F14: Wine | G14: BL981007
A15: SC2BL981009 | B15: 43922 | D15: Custom | E15: Cozy Match | F15: Pomegranate | G15: BL981009
A16: SC2BL981031 | B16: 45383 | D16: Custom | E16: Cozy Match | F16: Oyster | G16: BL981031
A17: SC2BL981036 | B17: 43922 | D17: Custom | E17: Cozy Match | F17: Marshmallow | G17: BL981036
A18: SC2BL981050 | B18: 43922 | D18: Custom | E18: Cozy Match | F18: Licorice | G18: BL981050
A19: SC2BL981051 | B19: 43922 | D19: Custom | E19: Cozy Match | F19: Dusty | G19: BL981051
A20: SC2BL981054 | B20: 43922 | D20: Custom | E20: Cozy Match | F20: Putty | G20: BL981054
... A53: SC2FL941950 | B53: 39601 | D53: Custom Plus | E53: Samba | F53: Ebony | G53: FL941950
A54: SC2FL941953 | B54: 39601 | C54: 43208 | D54: Custom Plus | E54: Samba | F54: Gray | G54: FL941953
A55: SC2FL941965 | B55: 39601 | D55: Custom Plus | E55: Samba | F55: Cobblestone | G55: FL941965
A56: SC2FL941982 | B56: 39601 | D56: Custom Plus | E56: Samba | F56: Powder Blue | G56: FL941982
A57: SC2FL941987 | B57: 39601 | D57: Custom Plus | E57: Samba | F57: Ultramarine | G57: FL941987
A58: SC2FL941996 | B58: 44835 | D58: Custom Plus | E58: Samba | F58: Aqua | G58: FL941996
A59: SL2HL190677 | B59: 45931 | D59: Specialty | E59: Ankur | F59: Brown | G59: HL190677
A60: SL2HL190673 | B60: 45931 | D60: Specialty | E60: Ankur | F60: Oak | G60: HL190673
A61: SL2HL190675 | B61: 45931 | D61: Specialty | E61: Ankur | F61: Saddle | G61: HL190675
A62: SL2HL190679 | B62: 45931 | D62: Specialty | E62: Ankur | F62: Walnut | G62: HL190679
A63: SL2FL190754 | B63: 45931 | D63: Specialty | E63: Aline | F63: Light Grey | G63: FL190754
A64: SL2FL190736 | B64: 45931 | D64: Specialty | E64: Aline | F64: Stonewash | G64: FL190736
A65: SL2FL190784 | B65: 45931 | D65: Specialty | E65: Aline | F65: Haze | G65: FL190784
A66: SL2FL190787 | B66: 45931 | D66: Specialty | E66: Aline | F66: Dark Blue | G66: FL190787
... A86: SL2FL207886 | B86: 45931 | D86: Specialty | E86: Manchester | F86: Midnight | G86: FL207886
A88: DROPPED
A89: SC2FL941908 | B89: 44835 | D89: Custom Plus | E89: Samba | F89: Crimson | G89: FL941908
A90: SC2FL941942 | B90: 44835 | D90: Custom Plus | E90: Samba | F90: Marigold | G90: FL941942
A91: SC2FL941962 | B91: 44835 | D91: Custom Plus | E91: Samba | F91: Clay | G91: FL941962
A92: SC2FL152352 | B92: 42826 | D92: Custom Plus | E92: Great Smokies | F92: Tin | G92: FL152352
A93: SC2FL152357 | B93: 42826 | D93: Custom Plus | E93: Great Smokies | F93: Smoke | G93: FL152357
...

Sheet Custom Leather Plus
A1: The following swatches for the La-Z-Boy Custom Leather Plus represent current offerings as of the April 2026 Market.
A2: EX | J2: Key:
J3: Immediate Drop
A4: Custom Leather Plus (New Logo) | B4: Cover | C4: 000097-A | J4: Phase Outs
A5: Custom Leather Plus (French) | B5: Cover | C5: MS0380FR | J5: New Phase Outs
J6: April 2026 Drops
A8: Item Number | B8: Intro Dates | C8: Date Last Updated | D8: S=Single, C=Correlate, W/F=Waterfall, P/S=Postage Stamp | E8: Pattern Name | F8: Cover1 | G8: Cover2 | H8: Cover3 | I8: Cover4 | J8: Cover5 | K8: Cover6 | L8: Cover7
A9: SCPDL159574 | B9: 43191 | C9: 44652 | D9: P/S | E9: Montana | F9: DL159574 | G9: DL159557
A10: SCPDL159658 | B10: 43191 | D10: P/S | E10: Titan | F10: DL159658 | G10: DL159675 | H10: DL159674 | I10: DL159665 | J10: DL159651
A11: SCPDL213086 | B11: 46113 | D11: P/S | E11: Atlantis | F11: DL213086 | G11: DL213059 | H11: DL213073 | I11: DL213077
A12: SCPFL200359 | B12: 45200 | D12: P/S | E12: Jesi | F12: FL200359 | G12: FL200375 | H12: FL200363 | I12: FL200372 | J12: FL200377 | K12: FL200307
A13: SCPFL202651 | B13: 45383 | D13: P/S | E13: Grandview | F13: FL202651 | G13: FL202698 | H13: FL202659 | I13: FL202675
A14: SCPFL941917 | B14: 44835 | C14: 46113 | D14: P/S | E14: Samba | F14: FL941917 | G14: FL941996 | H14: FL941962 | I14: FL941926 | J14: FL941942 | K14: FL941908 | L14: FL941928
A15: SCPFL941950 | B15: 44835 | D15: P/S | E15: Samba | F15: FL941950 | G15: FL941953 | H15: FL941930 | I15: FL941987 | J15: FL941932 | K15: FL941965 | L15: FL941982
A17: Please remove the following flags from your Custom Leather Plus Collection
A18: SCPFL152379 | B18: 42826 | D18: P/S | E18: Great Smokies | F18: FL152379 | G18: FL152375 | H18: FL152373 | I18: FL152352 | J18: FL152357
A19: SCWFL196357 | B19: 45017 | D19: W/F | E19: Gramado | F19: FL196357 | G19: FL196379 | H19: FL196373 | I19: FL196376

Sheet Custom Leather
A1: The following swatches for the La-Z-Boy Custom Leather Match represent current offerings as of the April 2026 Market.
A2: EX | J2: Key:
J3: Immediate Drop
A4: Custom Leather (New Logo) | B4: Cover | C4: 000096-A | J4: Phase Outs
A5: Custom Leather (French) | B5: Cover | C5: MS0379FR | J5: New Phase Outs
J6: April 2026 Drops
A8: Item Number | B8: Intro Date | C8: Date Last Updated | D8: S=Single, C=Correlate, W/F=Waterfall, P/S=Postage Stamp | E8: Pattern | F8: Cover1 | G8: Cover2 | H8: Cover3 | I8: Cover4 | J8: Cover5 | K8: Cover6 | L8: Cover7
A9: SCPBL211773 | B9: 46113 | D9: P/S | E9: Majestic Match | F9: BL211773 | G9: BL211778 | H9: BL211758 | I9: BL211786 | J9: BL211763
A10: SCPBL981078 | B10: 43922 | D10: P/S | E10: Cozy Match | F10: BL981078 | G10: BL981007 | H10: BL981009 | I10: BL981076 | J10: BL981087
A11: SCPBL981056 | B11: 43922 | D11: P/S | E11: Cozy Match | F11: BL981056 | G11: BL981036 | H11: BL981051 | I11: BL981054 | J11: BL981050
A12: SCPBL981098 | B12: 45383 | D12: P/S | E12: Cozy Match | F12: BL981098 | G12: BL981090 | H12: BL981031
A16: Please remove the following flags from your Custom Leather Collection.

Sheet Specialty Leather Handle
A1: The following swatches for the La-Z-Boy Specialty Leather Collection represent current offerings as of the April 2026 Market.
A4: Specialty Leather 12x12 | B4: Cover | C4: MS0397
A5: Antimicrobial Leather Divider | B5: Divider | C5: MS0398
A6: Analine Leather Divider | B6: Divider | C6: MS0328
A7: iClean Leather Divider | B7: Divider | C7: MS0400
A9: Item Number 12x12 Swatch | B9: Intro Date | C9: Date Last Updated | D9: Pattern Name | E9: Color Name | F9: Cover1
A10: Specialty Leather Cover
A11: Antimicrobial Divider
A12: HL190677 | B12: 44652 | D12: Ankur | E12: Brown | F12: HL190677
A13: HL190673 | B13: 44652 | D13: Ankur | E13: Oak | F13: HL190673
A14: HL190675 | B14: 44652 | D14: Ankur | E14: Saddle | F14: HL190675
A15: HL190679 | B15: 44652 | D15: Ankur | E15: Walnut | F15: HL190679
A16: FL190754 | B16: 44652 | D16: Aline | E16: Light Grey | F16: FL190754
A17: FL190736 | B17: 44652 | D17: Aline | E17: Stonewash | F17: FL190736
A18: FL190784 | B18: 44652 | D18: Aline | E18: Haze | F18: FL190784
A19: FL190787 | B19: 44652 | D19: Aline | E19: Dark Blue | F19: FL190787
A20: FL190758 | B20: 44652 | D20: Aline | E20: Storm | F20: FL190758
A21: FL190777 | B21: 44652 | D21: Aline | E21: Chocolate | F21: FL190777
A22: Aniline Divider
A23: iClean Divider
A24: SL1DL196236 | B24: 45017 | D24: Jazz | E24: Moonbeam | F24: DL196236
A25: SL1DL196258 | B25: 45017 | D25: Jazz | E25: Charcoal | F25: DL196258
A26: SL1DL196275 | B26: 45017 | D26: Jazz | E26: Cinnamon | F26: DL196275
A27: SL1DL196278 | B27: 45017 | D27: Jazz | E27: Coffee | F27: DL196278
A28: SL1DL196286 | B28: 45017 | D28: Jazz | E28: Midnight Blue | F28: DL196286
A29: FL193208 | B29: 44835 | D29: Athena | E29: Burgundy | F29: FL193208
A30: FL193255 | B30: 44835 | D30: Athena | E30: Grey | F30: FL193255
A31: FL193259 | B31: 44835 | D31: Athena | E31: Carbon | F31: FL193259
A32: FL193263 | B32: 44835 | D32: Athena | E32: Ash | F32: FL193263
A33: FL193273 | B33: 44835 | D33: Athena | E33: Oak | F33: FL193273
A34: FL193277 | B34: 44835 | D34: Athena | E34: Brown | F34: FL193277
A35: FL193284 | B35: 44835 | D35: Athena | E35: Granite Grey | F35: FL193284
... A41: SL1FL207886A | B41: 46113 | D41: Manchester | E41: Midnight | F41: FL207886
A45: Please remove the following flags from your La-Z-Boy Specialty Leather swatch set:
A46: SL1FL207886 | B46: 45748 | D46: Manchester | E46: Midnight | F46: FL207886

Sheet Specialty Leather Ring Page
A1: The following swatches for the La-Z-Boy Specialty Leather represent current offerings as of the April 2026 Market.
J2: Key:
A3: Single ring pages can be ordered through EPI using the code in Column A. These offerings are not available as a set and market updates will not be sent out automatically. You can order a cover for the Specialty Ring Pages through EPI with code: MS0406 | J3: Immediate Drop
J4: Phase Outs
J5: New Phase Outs
A6: Specialty Leather Ring Page Cover | C6: MS0406 | J6: April 2026 Drops
A8: Item Number | B8: Intro Dates | C8: Date Last Updated | D8: S=Single, C=Correlate, W/F=Waterfall, P/S=Postage Stamp 2x3=20 | E8: Pattern Name | F8: Cover1 | G8: Cover2 | H8: Cover3 | I8: Cover4 | J8: Cover5 | K8: Cover6 | L8: Cover7
A9: SLPHL190677 | B9: 45931 | D9: P/S | E9: Ankur | F9: HL190677 | G9: HL190673 | H9: HL190675 | I9: HL190679
A10: SLPFL190754 | B10: 45931 | D10: P/S | E10: Aline | F10: FL190754 | G10: FL190736 | H10: FL190784 | I10: FL190787 | J10: FL190758 | K10: FL190777
A11: SLPDL196236 | B11: 45931 | D11: P/S | E11: Jazz | F11: DL196236 | G11: DL196278 | H11: DL196286 | I11: DL196275 | J11: DL196258
A12: SLPFL193277 | B12: 45931 | D12: P/S | E12: Athena | F12: FL193277 | G12: FL193263 | H12: FL193208 | I12: FL193255 | J12: FL193284 | K12: FL193273 | L12: FL193259
